Workbook

Sheet Cover
A1: AssetLens - Asset & Wealth Management P&L, profitability and pricing model
A3: Version | B3: 1.0 (Phase 1) - built 2026-10-21
A4: Master check | B4: =IF(Checks!B19<0.001,"ALL CHECKS PASS","CHECK FAILURE - see Checks sheet")
A5: Scenario | B5: =Scenarios!B2
A7: Purpose | B7: Driver-based 8-quarter P&L forecast of the GS AWM segment under bull/base/bear/stress scenarios, with budget variance, fully allocated profitability, mandate pricing and a GCC expansion case.
A8: Colour code | B8: Blue = input / pasted data; black = formula; green = link to another sheet.
A9: Sheets | B9: Inputs · Scenarios · AUM_Rollforward · Revenue · Expenses · PnL · Budget_Variance · Profitability · Mandate_Pricing · Growth_Case · Sensitivity · Benchmarks · Checks
A10: Sign convention | B10: Revenues positive; costs shown positive in Expenses and subtracted in PnL; $ millions unless stated.
A12: Disclaimer | B12: AssetLens is an independent educational project built from publicly available SEC filings and FRED data. It is not affiliated with, endorsed by, or based on any non-public information from Goldman Sachs or any other company named. Business-unit, headcount, advisor, expense and compensation data are synthetic, generated to be consistent with public segment totals, and do not represent any company's internal figures. Nothing here is investment advice.

Sheet Inputs
A1: Inputs - public base data and modelling assumptions ($ millions unless stated)
A3: Item | B3: Value | C3: Unit | D3: Source / note
A4: Base-quarter management & other fees (Q3-26) | B4: 3587 | C4: $m | D4: GS 8-K Ex.99.1 3Q26 (public)
A5: Base private banking & lending revenue (Q3-26) | B5: 827 | C5: $m | D5: GS 8-K Ex.99.1 3Q26 (public)
A6: Investments revenue - average of last 8 quarters | B6: 405.25 | C6: $m | D6: GS 10-Q/10-K AWM table (public)
A7: Incentive fees - trailing four quarters | B7: 1063 | C7: $m | D7: GS 10-Q/10-K (public)
A8: Average alternatives AUS - trailing four quarters | B8: 435125 | C8: $m | D8: GS (public)
A9: Provision for credit losses - avg last 4 full-P&L quarters | B9: 16.25 | C9: $m | D9: GS (public)
A10: Operating expenses - avg last 4 full-P&L quarters | B10: 3324 | C10: $m | D10: GS (public)
A11: Net revenues - avg last 4 full-P&L quarters | B11: 4474.25 | C11: $m | D11: GS (public)
A12: Asset class | B12: AUS prev (Q2-26) $m | C12: AUS base (Q3-26) $m | D12: Relative yield (x) | E12: Fee compression p.a. | F12: Equity beta | G12: Carry / qtr | H12: Bond-return link (1=yes) | I12: Average AUS $m | J12: Initial annual yield
A13: alternatives | B13: 459000 | C13: 491000 | D13: 2.4 | E13: 0.02 | F13: 0.35 | G13: 0.01 | H13: 0 | I13: =(B13+C13)/2 | J13: =$B$18*D13
A14: equity | B14: 1123000 | C14: 1150000 | D14: 1 | E14: 0.03 | F14: 1 | G14: 0 | H14: 0 | I14: =(B14+C14)/2 | J14: =$B$18*D14
A15: fixed_income | B15: 1394000 | C15: 1405000 | D15: 0.55 | E15: 0.025 | F15: 0 | G15: 0 | H15: 1 | I15: =(B15+C15)/2 | J15: =$B$18*D15
A16: liquidity | B16: 1065000 | C16: 1051000 | D16: 0.12 | E16: 0.01 | F16: 0 | G16: 0 | H16: 0 | I16: =(B16+C16)/2 | J16: =$B$18*D16
A18: Fee-yield scale s (calibrates base fees) | B18: =B4*4/SUMPRODUCT(D13:D16,I13:I16)
A19: Compensation ratio target | B19: 0.446 | D19: GS FY2025 AWM segment comp / net revenues (public)
A20: Comp fixed floor (share of base comp) | B20: 0.85
A21: Variable non-comp (% of net revenue) | B21: 0.1
A22: Cost inflation p.a. | B22: 0.03
A23: PBL base net interest margin | B23: 0.025
A24: PBL margin beta to short rate | B24: 0.35
A25: PBL loan growth p.a. | B25: 0.05
A26: Base short rate r0 | B26: 0.0375
A27: Base-period compensation | B27: =B19*B11
A28: Compensation fixed floor ($m / qtr) | B28: =B20*B27 | D28: Formula
A29: Fixed non-comp ($m / qtr) | B29: =(B10-B27)-B21*B11
A30: Incentive rate (annual, on avg alternatives AUS) | B30: =B7/B8
A31: Incentive seasonality Q1 | B31: 0.2
A32: Incentive seasonality Q2 | B32: 0.2
A33: Incentive seasonality Q3 | B33: 0.22
A34: Incentive seasonality Q4 | B34: 0.38
A35: Quarter number of base quarter (Q3-26 = 3) | B35: 3

Sheet Scenarios
A1: Scenario selector - drives every sheet
A2: Selected scenario | B2: base
A4: Selected path | C4: t1 | D4: t2 | E4: t3 | F4: t4 | G4: t5 | H4: t6 | I4: t7 | J4: t8
A5: equity_ret_q | C5: =INDEX(C$20:C$59,MATCH($B$2&"|"&$A5,$L$20:$L$59,0)) | D5: =INDEX(D$20:D$59,MATCH($B$2&"|"&$A5,$L$20:$L$59,0)) | E5: =INDEX(E$20:E$59,MATCH($B$2&"|"&$A5,$L$20:$L$59,0)) | F5: =INDEX(F$20:F$59,MATCH($B$2&"|"&$A5,$L$20:$L$59,0)) | G5: =INDEX(G$20:G$59,MATCH($B$2&"|"&$A5,$L$20:$L$59,0)) | H5: =INDEX(H$20:H$59,MATCH($B$2&"|"&$A5,$L$20:$L$59,0)) | I5: =INDEX(I$20:I$59,MATCH($B$2&"|"&$A5,$L$20:$L$59,0)) | J5: =INDEX(J$20:J$59,MATCH($B$2&"|"&$A5,$L$20:$L$59,0))
A6: bond_ret_q | C6: =INDEX(C$20:C$59,MATCH($B$2&"|"&$A6,$L$20:$L$59,0)) | D6: =INDEX(D$20:D$59,MATCH($B$2&"|"&$A6,$L$20:$L$59,0)) | E6: =INDEX(E$20:E$59,MATCH($B$2&"|"&$A6,$L$20:$L$59,0)) | F6: =INDEX(F$20:F$59,MATCH($B$2&"|"&$A6,$L$20:$L$59,0)) | G6: =INDEX(G$20:G$59,MATCH($B$2&"|"&$A6,$L$20:$L$59,0)) | H6: =INDEX(H$20:H$59,MATCH($B$2&"|"&$A6,$L$20:$L$59,0)) | I6: =INDEX(I$20:I$59,MATCH($B$2&"|"&$A6,$L$20:$L$59,0)) | J6: =INDEX(J$20:J$59,MATCH($B$2&"|"&$A6,$L$20:$L$59,0))
A7: short_rate | C7: =INDEX(C$20:C$59,MATCH($B$2&"|"&$A7,$L$20:$L$59,0)) | D7: =INDEX(D$20:D$59,MATCH($B$2&"|"&$A7,$L$20:$L$59,0)) | E7: =INDEX(E$20:E$59,MATCH($B$2&"|"&$A7,$L$20:$L$59,0)) | F7: =INDEX(F$20:F$59,MATCH($B$2&"|"&$A7,$L$20:$L$59,0)) | G7: =INDEX(G$20:G$59,MATCH($B$2&"|"&$A7,$L$20:$L$59,0)) | H7: =INDEX(H$20:H$59,MATCH($B$2&"|"&$A7,$L$20:$L$59,0)) | I7: =INDEX(I$20:I$59,MATCH($B$2&"|"&$A7,$L$20:$L$59,0)) | J7: =INDEX(J$20:J$59,MATCH($B$2&"|"&$A7,$L$20:$L$59,0))
A8: org_alternatives | C8: =INDEX(C$20:C$59,MATCH($B$2&"|"&$A8,$L$20:$L$59,0)) | D8: =INDEX(D$20:D$59,MATCH($B$2&"|"&$A8,$L$20:$L$59,0)) | E8: =INDEX(E$20:E$59,MATCH($B$2&"|"&$A8,$L$20:$L$59,0)) | F8: =INDEX(F$20:F$59,MATCH($B$2&"|"&$A8,$L$20:$L$59,0)) | G8: =INDEX(G$20:G$59,MATCH($B$2&"|"&$A8,$L$20:$L$59,0)) | H8: =INDEX(H$20:H$59,MATCH($B$2&"|"&$A8,$L$20:$L$59,0)) | I8: =INDEX(I$20:I$59,MATCH($B$2&"|"&$A8,$L$20:$L$59,0)) | J8: =INDEX(J$20:J$59,MATCH($B$2&"|"&$A8,$L$20:$L$59,0))
A9: org_equity | C9: =INDEX(C$20:C$59,MATCH($B$2&"|"&$A9,$L$20:$L$59,0)) | D9: =INDEX(D$20:D$59,MATCH($B$2&"|"&$A9,$L$20:$L$59,0)) | E9: =INDEX(E$20:E$59,MATCH($B$2&"|"&$A9,$L$20:$L$59,0)) | F9: =INDEX(F$20:F$59,MATCH($B$2&"|"&$A9,$L$20:$L$59,0)) | G9: =INDEX(G$20:G$59,MATCH($B$2&"|"&$A9,$L$20:$L$59,0)) | H9: =INDEX(H$20:H$59,MATCH($B$2&"|"&$A9,$L$20:$L$59,0)) | I9: =INDEX(I$20:I$59,MATCH($B$2&"|"&$A9,$L$20:$L$59,0)) | J9: =INDEX(J$20:J$59,MATCH($B$2&"|"&$A9,$L$20:$L$59,0))
A10: org_fixed_income | C10: =INDEX(C$20:C$59,MATCH($B$2&"|"&$A10,$L$20:$L$59,0)) | D10: =INDEX(D$20:D$59,MATCH($B$2&"|"&$A10,$L$20:$L$59,0)) | E10: =INDEX(E$20:E$59,MATCH($B$2&"|"&$A10,$L$20:$L$59,0)) | F10: =INDEX(F$20:F$59,MATCH($B$2&"|"&$A10,$L$20:$L$59,0)) | G10: =INDEX(G$20:G$59,MATCH($B$2&"|"&$A10,$L$20:$L$59,0)) | H10: =INDEX(H$20:H$59,MATCH($B$2&"|"&$A10,$L$20:$L$59,0)) | I10: =INDEX(I$20:I$59,MATCH($B$2&"|"&$A10,$L$20:$L$59,0)) | J10: =INDEX(J$20:J$59,MATCH($B$2&"|"&$A10,$L$20:$L$59,0))
A11: org_liquidity | C11: =INDEX(C$20:C$59,MATCH($B$2&"|"&$A11,$L$20:$L$59,0)) | D11: =INDEX(D$20:D$59,MATCH($B$2&"|"&$A11,$L$20:$L$59,0)) | E11: =INDEX(E$20:E$59,MATCH($B$2&"|"&$A11,$L$20:$L$59,0)) | F11: =INDEX(F$20:F$59,MATCH($B$2&"|"&$A11,$L$20:$L$59,0)) | G11: =INDEX(G$20:G$59,MATCH($B$2&"|"&$A11,$L$20:$L$59,0)) | H11: =INDEX(H$20:H$59,MATCH($B$2&"|"&$A11,$L$20:$L$59,0)) | I11: =INDEX(I$20:I$59,MATCH($B$2&"|"&$A11,$L$20:$L$59,0)) | J11: =INDEX(J$20:J$59,MATCH($B$2&"|"&$A11,$L$20:$L$59,0))
A12: incentive_mult | C12: =INDEX(C$20:C$59,MATCH($B$2&"|"&$A12,$L$20:$L$59,0)) | D12: =INDEX(D$20:D$59,MATCH($B$2&"|"&$A12,$L$20:$L$59,0)) | E12: =INDEX(E$20:E$59,MATCH($B$2&"|"&$A12,$L$20:$L$59,0)) | F12: =INDEX(F$20:F$59,MATCH($B$2&"|"&$A12,$L$20:$L$59,0)) | G12: =INDEX(G$20:G$59,MATCH($B$2&"|"&$A12,$L$20:$L$59,0)) | H12: =INDEX(H$20:H$59,MATCH($B$2&"|"&$A12,$L$20:$L$59,0)) | I12: =INDEX(I$20:I$59,MATCH($B$2&"|"&$A12,$L$20:$L$59,0)) | J12: =INDEX(J$20:J$59,MATCH($B$2&"|"&$A12,$L$20:$L$59,0))
A13: investments_mult | C13: =INDEX(C$20:C$59,MATCH($B$2&"|"&$A13,$L$20:$L$59,0)) | D13: =INDEX(D$20:D$59,MATCH($B$2&"|"&$A13,$L$20:$L$59,0)) | E13: =INDEX(E$20:E$59,MATCH($B$2&"|"&$A13,$L$20:$L$59,0)) | F13: =INDEX(F$20:F$59,MATCH($B$2&"|"&$A13,$L$20:$L$59,0)) | G13: =INDEX(G$20:G$59,MATCH($B$2&"|"&$A13,$L$20:$L$59,0)) | H13: =INDEX(H$20:H$59,MATCH($B$2&"|"&$A13,$L$20:$L$59,0)) | I13: =INDEX(I$20:I$59,MATCH($B$2&"|"&$A13,$L$20:$L$59,0)) | J13: =INDEX(J$20:J$59,MATCH($B$2&"|"&$A13,$L$20:$L$59,0))
A14: provision_mult | C14: =INDEX(C$20:C$59,MATCH($B$2&"|"&$A14,$L$20:$L$59,0)) | D14: =INDEX(D$20:D$59,MATCH($B$2&"|"&$A14,$L$20:$L$59,0)) | E14: =INDEX(E$20:E$59,MATCH($B$2&"|"&$A14,$L$20:$L$59,0)) | F14: =INDEX(F$20:F$59,MATCH($B$2&"|"&$A14,$L$20:$L$59,0)) | G14: =INDEX(G$20:G$59,MATCH($B$2&"|"&$A14,$L$20:$L$59,0)) | H14: =INDEX(H$20:H$59,MATCH($B$2&"|"&$A14,$L$20:$L$59,0)) | I14: =INDEX(I$20:I$59,MATCH($B$2&"|"&$A14,$L$20:$L$59,0)) | J14: =INDEX(J$20:J$59,MATCH($B$2&"|"&$A14,$L$20:$L$59,0))
A19: Scenario | B19: Parameter | C19: t1 | D19: t2 | E19: t3 | F19: t4 | G19: t5 | H19: t6 | I19: t7 | J19: t8 | L19: key
A20: base | B20: equity_ret_q | C20: 0.02 | D20: 0.02 | E20: 0.02 | F20: 0.02 | G20: 0.02 | H20: 0.02 | I20: 0.02 | J20: 0.02 | L20: =A20&"|"&B20
A21: base | B21: bond_ret_q | C21: 0.01 | D21: 0.01 | E21: 0.01 | F21: 0.01 | G21: 0.01 | H21: 0.01 | I21: 0.01 | J21: 0.01 | L21: =A21&"|"&B21
A22: base | B22: short_rate | C22: 0.0375 | D22: 0.035 | E22: 0.035 | F22: 0.035 | G22: 0.035 | H22: 0.035 | I22: 0.035 | J22: 0.035 | L22: =A22&"|"&B22
A23: base | B23: org_alternatives | C23: 0.06 | D23: 0.06 | E23: 0.06 | F23: 0.06 | G23: 0.06 | H23: 0.06 | I23: 0.06 | J23: 0.06 | L23: =A23&"|"&B23
A24: base | B24: org_equity | C24: 0.04 | D24: 0.04 | E24: 0.04 | F24: 0.04 | G24: 0.04 | H24: 0.04 | I24: 0.04 | J24: 0.04 | L24: =A24&"|"&B24
A25: base | B25: org_fixed_income | C25: 0.05 | D25: 0.05 | E25: 0.05 | F25: 0.05 | G25: 0.05 | H25: 0.05 | I25: 0.05 | J25: 0.05 | L25: =A25&"|"&B25
A26: base | B26: org_liquidity | C26: 0.03 | D26: 0.03 | E26: 0.03 | F26: 0.03 | G26: 0.03 | H26: 0.03 | I26: 0.03 | J26: 0.03 | L26: =A26&"|"&B26
A27: base | B27: incentive_mult | C27: 1 | D27: 1 | E27: 1 | F27: 1 | G27: 1 | H27: 1 | I27: 1 | J27: 1 | L27: =A27&"|"&B27
A28: base | B28: investments_mult | C28: 1 | D28: 1 | E28: 1 | F28: 1 | G28: 1 | H28: 1 | I28: 1 | J28: 1 | L28: =A28&"|"&B28
A29: base | B29: provision_mult | C29: 1 | D29: 1 | E29: 1 | F29: 1 | G29: 1 | H29: 1 | I29: 1 | J29: 1 | L29: =A29&"|"&B29
A30: bull | B30: equity_ret_q | C30: 0.04 | D30: 0.035 | E30: 0.035 | F30: 0.03 | G30: 0.03 | H30: 0.03 | I30: 0.03 | J30: 0.03 | L30: =A30&"|"&B30
A31: bull | B31: bond_ret_q | C31: 0.015 | D31: 0.015 | E31: 0.012 | F31: 0.012 | G31: 0.012 | H31: 0.012 | I31: 0.012 | J31: 0.012 | L31: =A31&"|"&B31
... A59: stress | B59: provision_mult | C59: 3 | D59: 3 | E59: 3 | F59: 3 | G59: 3 | H59: 3 | I59: 3 | J59: 3 | L59: =A59&"|"&B59

Sheet AUM_Rollforward
A1: AUS roll-forward by asset class ($m)
A2: t (quarters ahead) | C2: 1 | D2: 2 | E2: 3 | F2: 4 | G2: 5 | H2: 6 | I2: 7 | J2: 8
A3: Line | B3: t0 (Q3-26) | C3: t1 | D3: t2 | E3: t3 | F3: t4 | G3: t5 | H3: t6 | I3: t7 | J3: t8
C4: Q4-26 | D4: Q1-26 | E4: Q2-27 | F4: Q3-27 | G4: Q4-27 | H4: Q1-27 | I4: Q2-28 | J4: Q3-28
A5: Calendar quarter number | C5: =MOD(Inputs!$B$35+C$2-1,4)+1 | D5: =MOD(Inputs!$B$35+D$2-1,4)+1 | E5: =MOD(Inputs!$B$35+E$2-1,4)+1 | F5: =MOD(Inputs!$B$35+F$2-1,4)+1 | G5: =MOD(Inputs!$B$35+G$2-1,4)+1 | H5: =MOD(Inputs!$B$35+H$2-1,4)+1 | I5: =MOD(Inputs!$B$35+I$2-1,4)+1 | J5: =MOD(Inputs!$B$35+J$2-1,4)+1
A7: alternatives
A8: Beginning AUS | C8: =B12 | D8: =C12 | E8: =D12 | F8: =E12 | G8: =F12 | H8: =G12 | I8: =H12 | J8: =I12
A9: Market return (qtr) | C9: =Inputs!$F$13*Scenarios!C$5+Inputs!$G$13+Inputs!$H$13*Scenarios!C$6 | D9: =Inputs!$F$13*Scenarios!D$5+Inputs!$G$13+Inputs!$H$13*Scenarios!D$6 | E9: =Inputs!$F$13*Scenarios!E$5+Inputs!$G$13+Inputs!$H$13*Scenarios!E$6 | F9: =Inputs!$F$13*Scenarios!F$5+Inputs!$G$13+Inputs!$H$13*Scenarios!F$6 | G9: =Inputs!$F$13*Scenarios!G$5+Inputs!$G$13+Inputs!$H$13*Scenarios!G$6 | H9: =Inputs!$F$13*Scenarios!H$5+Inputs!$G$13+Inputs!$H$13*Scenarios!H$6 | I9: =Inputs!$F$13*Scenarios!I$5+Inputs!$G$13+Inputs!$H$13*Scenarios!I$6 | J9: =Inputs!$F$13*Scenarios!J$5+Inputs!$G$13+Inputs!$H$13*Scenarios!J$6
A10: Market impact | C10: =C8*C9 | D10: =D8*D9 | E10: =E8*E9 | F10: =F8*F9 | G10: =G8*G9 | H10: =H8*H9 | I10: =I8*I9 | J10: =J8*J9
A11: Net flows | C11: =Scenarios!C$8/4*C8 | D11: =Scenarios!D$8/4*D8 | E11: =Scenarios!E$8/4*E8 | F11: =Scenarios!F$8/4*F8 | G11: =Scenarios!G$8/4*G8 | H11: =Scenarios!H$8/4*H8 | I11: =Scenarios!I$8/4*I8 | J11: =Scenarios!J$8/4*J8
A12: Ending AUS | B12: =Inputs!C13 | C12: =C8+C10+C11 | D12: =D8+D10+D11 | E12: =E8+E10+E11 | F12: =F8+F10+F11 | G12: =G8+G10+G11 | H12: =H8+H10+H11 | I12: =I8+I10+I11 | J12: =J8+J10+J11
A13: equity
A14: Beginning AUS | C14: =B18 | D14: =C18 | E14: =D18 | F14: =E18 | G14: =F18 | H14: =G18 | I14: =H18 | J14: =I18
A15: Market return (qtr) | C15: =Inputs!$F$14*Scenarios!C$5+Inputs!$G$14+Inputs!$H$14*Scenarios!C$6 | D15: =Inputs!$F$14*Scenarios!D$5+Inputs!$G$14+Inputs!$H$14*Scenarios!D$6 | E15: =Inputs!$F$14*Scenarios!E$5+Inputs!$G$14+Inputs!$H$14*Scenarios!E$6 | F15: =Inputs!$F$14*Scenarios!F$5+Inputs!$G$14+Inputs!$H$14*Scenarios!F$6 | G15: =Inputs!$F$14*Scenarios!G$5+Inputs!$G$14+Inputs!$H$14*Scenarios!G$6 | H15: =Inputs!$F$14*Scenarios!H$5+Inputs!$G$14+Inputs!$H$14*Scenarios!H$6 | I15: =Inputs!$F$14*Scenarios!I$5+Inputs!$G$14+Inputs!$H$14*Scenarios!I$6 | J15: =Inputs!$F$14*Scenarios!J$5+Inputs!$G$14+Inputs!$H$14*Scenarios!J$6
A16: Market impact | C16: =C14*C15 | D16: =D14*D15 | E16: =E14*E15 | F16: =F14*F15 | G16: =G14*G15 | H16: =H14*H15 | I16: =I14*I15 | J16: =J14*J15
A17: Net flows | C17: =Scenarios!C$9/4*C14 | D17: =Scenarios!D$9/4*D14 | E17: =Scenarios!E$9/4*E14 | F17: =Scenarios!F$9/4*F14 | G17: =Scenarios!G$9/4*G14 | H17: =Scenarios!H$9/4*H14 | I17: =Scenarios!I$9/4*I14 | J17: =Scenarios!J$9/4*J14
A18: Ending AUS | B18: =Inputs!C14 | C18: =C14+C16+C17 | D18: =D14+D16+D17 | E18: =E14+E16+E17 | F18: =F14+F16+F17 | G18: =G14+G16+G17 | H18: =H14+H16+H17 | I18: =I14+I16+I17 | J18: =J14+J16+J17
A19: fixed_income
A20: Beginning AUS | C20: =B24 | D20: =C24 | E20: =D24 | F20: =E24 | G20: =F24 | H20: =G24 | I20: =H24 | J20: =I24
A21: Market return (qtr) | C21: =Inputs!$F$15*Scenarios!C$5+Inputs!$G$15+Inputs!$H$15*Scenarios!C$6 | D21: =Inputs!$F$15*Scenarios!D$5+Inputs!$G$15+Inputs!$H$15*Scenarios!D$6 | E21: =Inputs!$F$15*Scenarios!E$5+Inputs!$G$15+Inputs!$H$15*Scenarios!E$6 | F21: =Inputs!$F$15*Scenarios!F$5+Inputs!$G$15+Inputs!$H$15*Scenarios!F$6 | G21: =Inputs!$F$15*Scenarios!G$5+Inputs!$G$15+Inputs!$H$15*Scenarios!G$6 | H21: =Inputs!$F$15*Scenarios!H$5+Inputs!$G$15+Inputs!$H$15*Scenarios!H$6 | I21: =Inputs!$F$15*Scenarios!I$5+Inputs!$G$15+Inputs!$H$15*Scenarios!I$6 | J21: =Inputs!$F$15*Scenarios!J$5+Inputs!$G$15+Inputs!$H$15*Scenarios!J$6
A22: Market impact | C22: =C20*C21 | D22: =D20*D21 | E22: =E20*E21 | F22: =F20*F21 | G22: =G20*G21 | H22: =H20*H21 | I22: =I20*I21 | J22: =J20*J21
A23: Net flows | C23: =Scenarios!C$10/4*C20 | D23: =Scenarios!D$10/4*D20 | E23: =Scenarios!E$10/4*E20 | F23: =Scenarios!F$10/4*F20 | G23: =Scenarios!G$10/4*G20 | H23: =Scenarios!H$10/4*H20 | I23: =Scenarios!I$10/4*I20 | J23: =Scenarios!J$10/4*J20
A24: Ending AUS | B24: =Inputs!C15 | C24: =C20+C22+C23 | D24: =D20+D22+D23 | E24: =E20+E22+E23 | F24: =F20+F22+F23 | G24: =G20+G22+G23 | H24: =H20+H22+H23 | I24: =I20+I22+I23 | J24: =J20+J22+J23
A25: liquidity
A26: Beginning AUS | C26: =B30 | D26: =C30 | E26: =D30 | F26: =E30 | G26: =F30 | H26: =G30 | I26: =H30 | J26: =I30
A27: Market return (qtr) | C27: =Inputs!$F$16*Scenarios!C$5+Inputs!$G$16+Inputs!$H$16*Scenarios!C$6 | D27: =Inputs!$F$16*Scenarios!D$5+Inputs!$G$16+Inputs!$H$16*Scenarios!D$6 | E27: =Inputs!$F$16*Scenarios!E$5+Inputs!$G$16+Inputs!$H$16*Scenarios!E$6 | F27: =Inputs!$F$16*Scenarios!F$5+Inputs!$G$16+Inputs!$H$16*Scenarios!F$6 | G27: =Inputs!$F$16*Scenarios!G$5+Inputs!$G$16+Inputs!$H$16*Scenarios!G$6 | H27: =Inputs!$F$16*Scenarios!H$5+Inputs!$G$16+Inputs!$H$16*Scenarios!H$6 | I27: =Inputs!$F$16*Scenarios!I$5+Inputs!$G$16+Inputs!$H$16*Scenarios!I$6 | J27: =Inputs!$F$16*Scenarios!J$5+Inputs!$G$16+Inputs!$H$16*Scenarios!J$6
A28: Market impact | C28: =C26*C27 | D28: =D26*D27 | E28: =E26*E27 | F28: =F26*F27 | G28: =G26*G27 | H28: =H26*H27 | I28: =I26*I27 | J28: =J26*J27
A29: Net flows | C29: =Scenarios!C$11/4*C26 | D29: =Scenarios!D$11/4*D26 | E29: =Scenarios!E$11/4*E26 | F29: =Scenarios!F$11/4*F26 | G29: =Scenarios!G$11/4*G26 | H29: =Scenarios!H$11/4*H26 | I29: =Scenarios!I$11/4*I26 | J29: =Scenarios!J$11/4*J26
A30: Ending AUS | B30: =Inputs!C16 | C30: =C26+C28+C29 | D30: =D26+D28+D29 | E30: =E26+E28+E29 | F30: =F26+F28+F29 | G30: =G26+G28+G29 | H30: =H26+H28+H29 | I30: =I26+I28+I29 | J30: =J26+J28+J29
A31: Total
A32: Beginning AUS | C32: =C8+C14+C20+C26 | D32: =D8+D14+D20+D26 | E32: =E8+E14+E20+E26 | F32: =F8+F14+F20+F26 | G32: =G8+G14+G20+G26 | H32: =H8+H14+H20+H26 | I32: =I8+I14+I20+I26 | J32: =J8+J14+J20+J26
A33: Net flows | C33: =C11+C17+C23+C29 | D33: =D11+D17+D23+D29 | E33: =E11+E17+E23+E29 | F33: =F11+F17+F23+F29 | G33: =G11+G17+G23+G29 | H33: =H11+H17+H23+H29 | I33: =I11+I17+I23+I29 | J33: =J11+J17+J23+J29
A34: Market impact | C34: =C10+C16+C22+C28 | D34: =D10+D16+D22+D28 | E34: =E10+E16+E22+E28 | F34: =F10+F16+F22+F28 | G34: =G10+G16+G22+G28 | H34: =H10+H16+H22+H28 | I34: =I10+I16+I22+I28 | J34: =J10+J16+J22+J28
A35: Ending AUS | B35: =B12+B18+B24+B30 | C35: =C12+C18+C24+C30 | D35: =D12+D18+D24+D30 | E35: =E12+E18+E24+E30 | F35: =F12+F18+F24+F30 | G35: =G12+G18+G24+G30 | H35: =H12+H18+H24+H30 | I35: =I12+I18+I24+I30 | J35: =J12+J18+J24+J30

Sheet Revenue
A1: Revenue build ($m)
A2: t (quarters ahead) | C2: 1 | D2: 2 | E2: 3 | F2: 4 | G2: 5 | H2: 6 | I2: 7 | J2: 8
A3: Line | C3: t1 | D3: t2 | E3: t3 | F3: t4 | G3: t5 | H3: t6 | I3: t7 | J3: t8
C4: Q4-26 | D4: Q1-26 | E4: Q2-27 | F4: Q3-27 | G4: Q4-27 | H4: Q1-27 | I4: Q2-28 | J4: Q3-28
A5: alternatives: average AUS | C5: =(AUM_Rollforward!C8+AUM_Rollforward!C12)/2 | D5: =(AUM_Rollforward!D8+AUM_Rollforward!D12)/2 | E5: =(AUM_Rollforward!E8+AUM_Rollforward!E12)/2 | F5: =(AUM_Rollforward!F8+AUM_Rollforward!F12)/2 | G5: =(AUM_Rollforward!G8+AUM_Rollforward!G12)/2 | H5: =(AUM_Rollforward!H8+AUM_Rollforward!H12)/2 | I5: =(AUM_Rollforward!I8+AUM_Rollforward!I12)/2 | J5: =(AUM_Rollforward!J8+AUM_Rollforward!J12)/2
A6: alternatives: annual fee yield | C6: =Inputs!$J$13*(1-Inputs!$E$13)^(0.25*C$2) | D6: =Inputs!$J$13*(1-Inputs!$E$13)^(0.25*D$2) | E6: =Inputs!$J$13*(1-Inputs!$E$13)^(0.25*E$2) | F6: =Inputs!$J$13*(1-Inputs!$E$13)^(0.25*F$2) | G6: =Inputs!$J$13*(1-Inputs!$E$13)^(0.25*G$2) | H6: =Inputs!$J$13*(1-Inputs!$E$13)^(0.25*H$2) | I6: =Inputs!$J$13*(1-Inputs!$E$13)^(0.25*I$2) | J6: =Inputs!$J$13*(1-Inputs!$E$13)^(0.25*J$2)
A7: alternatives: management fees | C7: =C5*C6/4 | D7: =D5*D6/4 | E7: =E5*E6/4 | F7: =F5*F6/4 | G7: =G5*G6/4 | H7: =H5*H6/4 | I7: =I5*I6/4 | J7: =J5*J6/4
A8: equity: average AUS | C8: =(AUM_Rollforward!C14+AUM_Rollforward!C18)/2 | D8: =(AUM_Rollforward!D14+AUM_Rollforward!D18)/2 | E8: =(AUM_Rollforward!E14+AUM_Rollforward!E18)/2 | F8: =(AUM_Rollforward!F14+AUM_Rollforward!F18)/2 | G8: =(AUM_Rollforward!G14+AUM_Rollforward!G18)/2 | H8: =(AUM_Rollforward!H14+AUM_Rollforward!H18)/2 | I8: =(AUM_Rollforward!I14+AUM_Rollforward!I18)/2 | J8: =(AUM_Rollforward!J14+AUM_Rollforward!J18)/2
A9: equity: annual fee yield | C9: =Inputs!$J$14*(1-Inputs!$E$14)^(0.25*C$2) | D9: =Inputs!$J$14*(1-Inputs!$E$14)^(0.25*D$2) | E9: =Inputs!$J$14*(1-Inputs!$E$14)^(0.25*E$2) | F9: =Inputs!$J$14*(1-Inputs!$E$14)^(0.25*F$2) | G9: =Inputs!$J$14*(1-Inputs!$E$14)^(0.25*G$2) | H9: =Inputs!$J$14*(1-Inputs!$E$14)^(0.25*H$2) | I9: =Inputs!$J$14*(1-Inputs!$E$14)^(0.25*I$2) | J9: =Inputs!$J$14*(1-Inputs!$E$14)^(0.25*J$2)
A10: equity: management fees | C10: =C8*C9/4 | D10: =D8*D9/4 | E10: =E8*E9/4 | F10: =F8*F9/4 | G10: =G8*G9/4 | H10: =H8*H9/4 | I10: =I8*I9/4 | J10: =J8*J9/4
A11: fixed_income: average AUS | C11: =(AUM_Rollforward!C20+AUM_Rollforward!C24)/2 | D11: =(AUM_Rollforward!D20+AUM_Rollforward!D24)/2 | E11: =(AUM_Rollforward!E20+AUM_Rollforward!E24)/2 | F11: =(AUM_Rollforward!F20+AUM_Rollforward!F24)/2 | G11: =(AUM_Rollforward!G20+AUM_Rollforward!G24)/2 | H11: =(AUM_Rollforward!H20+AUM_Rollforward!H24)/2 | I11: =(AUM_Rollforward!I20+AUM_Rollforward!I24)/2 | J11: =(AUM_Rollforward!J20+AUM_Rollforward!J24)/2
A12: fixed_income: annual fee yield | C12: =Inputs!$J$15*(1-Inputs!$E$15)^(0.25*C$2) | D12: =Inputs!$J$15*(1-Inputs!$E$15)^(0.25*D$2) | E12: =Inputs!$J$15*(1-Inputs!$E$15)^(0.25*E$2) | F12: =Inputs!$J$15*(1-Inputs!$E$15)^(0.25*F$2) | G12: =Inputs!$J$15*(1-Inputs!$E$15)^(0.25*G$2) | H12: =Inputs!$J$15*(1-Inputs!$E$15)^(0.25*H$2) | I12: =Inputs!$J$15*(1-Inputs!$E$15)^(0.25*I$2) | J12: =Inputs!$J$15*(1-Inputs!$E$15)^(0.25*J$2)
A13: fixed_income: management fees | C13: =C11*C12/4 | D13: =D11*D12/4 | E13: =E11*E12/4 | F13: =F11*F12/4 | G13: =G11*G12/4 | H13: =H11*H12/4 | I13: =I11*I12/4 | J13: =J11*J12/4
A14: liquidity: average AUS | C14: =(AUM_Rollforward!C26+AUM_Rollforward!C30)/2 | D14: =(AUM_Rollforward!D26+AUM_Rollforward!D30)/2 | E14: =(AUM_Rollforward!E26+AUM_Rollforward!E30)/2 | F14: =(AUM_Rollforward!F26+AUM_Rollforward!F30)/2 | G14: =(AUM_Rollforward!G26+AUM_Rollforward!G30)/2 | H14: =(AUM_Rollforward!H26+AUM_Rollforward!H30)/2 | I14: =(AUM_Rollforward!I26+AUM_Rollforward!I30)/2 | J14: =(AUM_Rollforward!J26+AUM_Rollforward!J30)/2
A15: liquidity: annual fee yield | C15: =Inputs!$J$16*(1-Inputs!$E$16)^(0.25*C$2) | D15: =Inputs!$J$16*(1-Inputs!$E$16)^(0.25*D$2) | E15: =Inputs!$J$16*(1-Inputs!$E$16)^(0.25*E$2) | F15: =Inputs!$J$16*(1-Inputs!$E$16)^(0.25*F$2) | G15: =Inputs!$J$16*(1-Inputs!$E$16)^(0.25*G$2) | H15: =Inputs!$J$16*(1-Inputs!$E$16)^(0.25*H$2) | I15: =Inputs!$J$16*(1-Inputs!$E$16)^(0.25*I$2) | J15: =Inputs!$J$16*(1-Inputs!$E$16)^(0.25*J$2)
A16: liquidity: management fees | C16: =C14*C15/4 | D16: =D14*D15/4 | E16: =E14*E15/4 | F16: =F14*F15/4 | G16: =G14*G15/4 | H16: =H14*H15/4 | I16: =I14*I15/4 | J16: =J14*J15/4
A17: Total management & other fees | C17: =C7+C10+C13+C16 | D17: =D7+D10+D13+D16 | E17: =E7+E10+E13+E16 | F17: =F7+F10+F13+F16 | G17: =G7+G10+G13+G16 | H17: =H7+H10+H13+H16 | I17: =I7+I10+I13+I16 | J17: =J7+J10+J13+J16
A18: Incentive seasonality weight | C18: =INDEX(Inputs!$B$31:$B$34,AUM_Rollforward!C$5) | D18: =INDEX(Inputs!$B$31:$B$34,AUM_Rollforward!D$5) | E18: =INDEX(Inputs!$B$31:$B$34,AUM_Rollforward!E$5) | F18: =INDEX(Inputs!$B$31:$B$34,AUM_Rollforward!F$5) | G18: =INDEX(Inputs!$B$31:$B$34,AUM_Rollforward!G$5) | H18: =INDEX(Inputs!$B$31:$B$34,AUM_Rollforward!H$5) | I18: =INDEX(Inputs!$B$31:$B$34,AUM_Rollforward!I$5) | J18: =INDEX(Inputs!$B$31:$B$34,AUM_Rollforward!J$5)
A19: Incentive fees | C19: =Inputs!$B$30*C5*C18*Scenarios!C$12 | D19: =Inputs!$B$30*D5*D18*Scenarios!D$12 | E19: =Inputs!$B$30*E5*E18*Scenarios!E$12 | F19: =Inputs!$B$30*F5*F18*Scenarios!F$12 | G19: =Inputs!$B$30*G5*G18*Scenarios!G$12 | H19: =Inputs!$B$30*H5*H18*Scenarios!H$12 | I19: =Inputs!$B$30*I5*I18*Scenarios!I$12 | J19: =Inputs!$B$30*J5*J18*Scenarios!J$12
A20: Private banking & lending | C20: =Inputs!$B$5*(1+Inputs!$B$25)^(C$2/4)*(1+Inputs!$B$24*(Scenarios!C$7-Inputs!$B$26)/Inputs!$B$23) | D20: =Inputs!$B$5*(1+Inputs!$B$25)^(D$2/4)*(1+Inputs!$B$24*(Scenarios!D$7-Inputs!$B$26)/Inputs!$B$23) | E20: =Inputs!$B$5*(1+Inputs!$B$25)^(E$2/4)*(1+Inputs!$B$24*(Scenarios!E$7-Inputs!$B$26)/Inputs!$B$23) | F20: =Inputs!$B$5*(1+Inputs!$B$25)^(F$2/4)*(1+Inputs!$B$24*(Scenarios!F$7-Inputs!$B$26)/Inputs!$B$23) | G20: =Inputs!$B$5*(1+Inputs!$B$25)^(G$2/4)*(1+Inputs!$B$24*(Scenarios!G$7-Inputs!$B$26)/Inputs!$B$23) | H20: =Inputs!$B$5*(1+Inputs!$B$25)^(H$2/4)*(1+Inputs!$B$24*(Scenarios!H$7-Inputs!$B$26)/Inputs!$B$23) | I20: =Inputs!$B$5*(1+Inputs!$B$25)^(I$2/4)*(1+Inputs!$B$24*(Scenarios!I$7-Inputs!$B$26)/Inputs!$B$23) | J20: =Inputs!$B$5*(1+Inputs!$B$25)^(J$2/4)*(1+Inputs!$B$24*(Scenarios!J$7-Inputs!$B$26)/Inputs!$B$23)
A21: Investments | C21: =Inputs!$B$6*Scenarios!C$13 | D21: =Inputs!$B$6*Scenarios!D$13 | E21: =Inputs!$B$6*Scenarios!E$13 | F21: =Inputs!$B$6*Scenarios!F$13 | G21: =Inputs!$B$6*Scenarios!G$13 | H21: =Inputs!$B$6*Scenarios!H$13 | I21: =Inputs!$B$6*Scenarios!I$13 | J21: =Inputs!$B$6*Scenarios!J$13
A22: Net revenues | C22: =C17+C19+C20+C21 | D22: =D17+D19+D20+D21 | E22: =E17+E19+E20+E21 | F22: =F17+F19+F20+F21 | G22: =G17+G19+G20+G21 | H22: =H17+H19+H20+H21 | I22: =I17+I19+I20+I21 | J22: =J17+J19+J20+J21
A23: Total average AUS | C23: =C5+C8+C11+C14 | D23: =D5+D8+D11+D14 | E23: =E5+E8+E11+E14 | F23: =F5+F8+F11+F14 | G23: =G5+G8+G11+G14 | H23: =H5+H8+H11+H14 | I23: =I5+I8+I11+I14 | J23: =J5+J8+J11+J14
A24: Effective fee yield (bps) | C24: =C17*4/C23*10000 | D24: =D17*4/D23*10000 | E24: =E17*4/E23*10000 | F24: =F17*4/F23*10000 | G24: =G17*4/G23*10000 | H24: =H17*4/H23*10000 | I24: =I17*4/I23*10000 | J24: =J17*4/J23*10000

Sheet Expenses
A1: Expenses ($m, shown positive)
A2: t (quarters ahead) | C2: 1 | D2: 2 | E2: 3 | F2: 4 | G2: 5 | H2: 6 | I2: 7 | J2: 8
A3: Line | C3: t1 | D3: t2 | E3: t3 | F3: t4 | G3: t5 | H3: t6 | I3: t7 | J3: t8
C4: Q4-26 | D4: Q1-26 | E4: Q2-27 | F4: Q3-27 | G4: Q4-27 | H4: Q1-27 | I4: Q2-28 | J4: Q3-28
A5: Compensation = MAX(fixed floor, ratio x net revenue) | C5: =MAX(Inputs!$B$28,Inputs!$B$19*Revenue!C22) | D5: =MAX(Inputs!$B$28,Inputs!$B$19*Revenue!D22) | E5: =MAX(Inputs!$B$28,Inputs!$B$19*Revenue!E22) | F5: =MAX(Inputs!$B$28,Inputs!$B$19*Revenue!F22) | G5: =MAX(Inputs!$B$28,Inputs!$B$19*Revenue!G22) | H5: =MAX(Inputs!$B$28,Inputs!$B$19*Revenue!H22) | I5: =MAX(Inputs!$B$28,Inputs!$B$19*Revenue!I22) | J5: =MAX(Inputs!$B$28,Inputs!$B$19*Revenue!J22)
A6: Non-compensation | C6: =Inputs!$B$29*(1+Inputs!$B$22)^(C$2/4)+Inputs!$B$21*Revenue!C22 | D6: =Inputs!$B$29*(1+Inputs!$B$22)^(D$2/4)+Inputs!$B$21*Revenue!D22 | E6: =Inputs!$B$29*(1+Inputs!$B$22)^(E$2/4)+Inputs!$B$21*Revenue!E22 | F6: =Inputs!$B$29*(1+Inputs!$B$22)^(F$2/4)+Inputs!$B$21*Revenue!F22 | G6: =Inputs!$B$29*(1+Inputs!$B$22)^(G$2/4)+Inputs!$B$21*Revenue!G22 | H6: =Inputs!$B$29*(1+Inputs!$B$22)^(H$2/4)+Inputs!$B$21*Revenue!H22 | I6: =Inputs!$B$29*(1+Inputs!$B$22)^(I$2/4)+Inputs!$B$21*Revenue!I22 | J6: =Inputs!$B$29*(1+Inputs!$B$22)^(J$2/4)+Inputs!$B$21*Revenue!J22
A7: Provision for credit losses | C7: =Inputs!$B$9*Scenarios!C$14 | D7: =Inputs!$B$9*Scenarios!D$14 | E7: =Inputs!$B$9*Scenarios!E$14 | F7: =Inputs!$B$9*Scenarios!F$14 | G7: =Inputs!$B$9*Scenarios!G$14 | H7: =Inputs!$B$9*Scenarios!H$14 | I7: =Inputs!$B$9*Scenarios!I$14 | J7: =Inputs!$B$9*Scenarios!J$14
A8: Total costs incl. provision | C8: =SUM(C5:C7) | D8: =SUM(D5:D7) | E8: =SUM(E5:E7) | F8: =SUM(F5:F7) | G8: =SUM(G5:G7) | H8: =SUM(H5:H7) | I8: =SUM(I5:I7) | J8: =SUM(J5:J7)

Sheet PnL
A1: P&L forecast - selected scenario ($m)
A2: Scenario: | B2: =Scenarios!B2
A3: Line | C3: t1 | D3: t2 | E3: t3 | F3: t4 | G3: t5 | H3: t6 | I3: t7 | J3: t8 | K3: Year 1 | L3: Year 2
C4: Q4-26 | D4: Q1-26 | E4: Q2-27 | F4: Q3-27 | G4: Q4-27 | H4: Q1-27 | I4: Q2-28 | J4: Q3-28
A5: Net revenues | C5: =Revenue!C22 | D5: =Revenue!D22 | E5: =Revenue!E22 | F5: =Revenue!F22 | G5: =Revenue!G22 | H5: =Revenue!H22 | I5: =Revenue!I22 | J5: =Revenue!J22 | K5: =SUM(C5:F5) | L5: =SUM(G5:J5)
A6: of which investments | C6: =Revenue!C21 | D6: =Revenue!D21 | E6: =Revenue!E21 | F6: =Revenue!F21 | G6: =Revenue!G21 | H6: =Revenue!H21 | I6: =Revenue!I21 | J6: =Revenue!J21 | K6: =SUM(C6:F6) | L6: =SUM(G6:J6)
A7: Compensation | C7: =Expenses!C5 | D7: =Expenses!D5 | E7: =Expenses!E5 | F7: =Expenses!F5 | G7: =Expenses!G5 | H7: =Expenses!H5 | I7: =Expenses!I5 | J7: =Expenses!J5 | K7: =SUM(C7:F7) | L7: =SUM(G7:J7)
A8: Non-compensation | C8: =Expenses!C6 | D8: =Expenses!D6 | E8: =Expenses!E6 | F8: =Expenses!F6 | G8: =Expenses!G6 | H8: =Expenses!H6 | I8: =Expenses!I6 | J8: =Expenses!J6 | K8: =SUM(C8:F8) | L8: =SUM(G8:J8)
A9: Provision for credit losses | C9: =Expenses!C7 | D9: =Expenses!D7 | E9: =Expenses!E7 | F9: =Expenses!F7 | G9: =Expenses!G7 | H9: =Expenses!H7 | I9: =Expenses!I7 | J9: =Expenses!J7 | K9: =SUM(C9:F9) | L9: =SUM(G9:J9)
A10: Pre-tax earnings | C10: =C5-C7-C8-C9 | D10: =D5-D7-D8-D9 | E10: =E5-E7-E8-E9 | F10: =F5-F7-F8-F9 | G10: =G5-G7-G8-G9 | H10: =H5-H7-H8-H9 | I10: =I5-I7-I8-I9 | J10: =J5-J7-J8-J9 | K10: =SUM(C10:F10) | L10: =SUM(G10:J10)
A11: Pre-tax margin | C11: =C10/C5 | D11: =D10/D5 | E11: =E10/E5 | F11: =F10/F5 | G11: =G10/G5 | H11: =H10/H5 | I11: =I10/I5 | J11: =J10/J5 | ... L11: =L10/L5
A12: Core pre-tax margin (ex Investments) | C12: =(C10-C6)/(C5-C6) | D12: =(D10-D6)/(D5-D6) | E12: =(E10-E6)/(E5-E6) | F12: =(F10-F6)/(F5-F6) | G12: =(G10-G6)/(G5-G6) | H12: =(H10-H6)/(H5-H6) | I12: =(I10-I6)/(I5-I6) | J12: =(J10-J6)/(J5-J6) | ... L12: =(L10-L6)/(L5-L6)
A13: Compensation ratio | C13: =C7/C5 | D13: =D7/D5 | E13: =E7/E5 | F13: =F7/F5 | G13: =G7/G5 | H13: =H7/H5 | I13: =I7/I5 | J13: =J7/J5 | ... L13: =L7/L5
A14: Ending AUS | C14: =AUM_Rollforward!C35 | D14: =AUM_Rollforward!D35 | E14: =AUM_Rollforward!E35 | F14: =AUM_Rollforward!F35 | G14: =AUM_Rollforward!G35 | H14: =AUM_Rollforward!H35 | I14: =AUM_Rollforward!I35 | J14: =AUM_Rollforward!J35
A16: Year-2 vs Year-1 net revenue growth | B16: =L5/K5-1

Sheet Budget_Variance
A1: Budget vs forecast vs prior year; price-volume-mix fee bridge ($m)
A3: Prior-year quarter (T4Q with full P&L) | B3: Net revenues | C3: Pre-tax earnings
A4: Q ending 2025-09-30 | B4: 4399 | C4: 1136
A5: Q ending 2025-12-31 | B5: 4823 | C5: 1358
A6: Q ending 2026-03-31 | B6: 4078 | C6: 930
A7: Q ending 2026-06-30 | B7: 4597 | C7: 1112
A8: Prior-year total | B8: =SUM(B4:B7) | C8: =SUM(C4:C7)
A10: Top-down revenue growth target | B10: 0.08 | C10: UNVERIFIED secondary-source target - confirm from primary material
A11: Top-down pre-tax margin target | B11: 0.3
A12: Variance threshold (%) | B12: 0.05
B14: Prior year | C14: Budget (top-down) | D14: Forecast Year 1 | E14: Variance vs budget | F14: Variance % | G14: Flag
A15: Net revenues | B15: =B8 | C15: =B15*(1+B10) | D15: =PnL!K5 | E15: =D15-C15 | F15: =E15/ABS(C15) | G15: =IF(ABS(F15)>$B$12,"REVIEW - owner commentary required","Within threshold")
A16: Pre-tax earnings | B16: =C8 | C16: =C15*B11 | D16: =PnL!K10 | E16: =D16-C16 | F16: =E16/ABS(C16) | G16: =IF(ABS(F16)>$B$12,"REVIEW - owner commentary required","Within threshold")
A19: Price-volume-mix bridge of management fees: Year-2 Q4 (t8) vs Year-1 Q4 (t4)
A20: Asset class | B20: Avg AUS t4 | C20: Fees t4 | D20: Avg AUS t8 | E20: Fees t8 | F20: Yield t4 | G20: Yield t8 | H20: Weight t4 | I20: Weight t8
A21: alternatives | B21: =Revenue!F5 | C21: =Revenue!F7 | D21: =Revenue!J5 | E21: =Revenue!J7 | F21: =C21/B21 | G21: =E21/D21 | H21: =B21/B$25 | I21: =D21/D$25
A22: equity | B22: =Revenue!F8 | C22: =Revenue!F10 | D22: =Revenue!J8 | E22: =Revenue!J10 | F22: =C22/B22 | G22: =E22/D22 | H22: =B22/B$25 | I22: =D22/D$25
A23: fixed_income | B23: =Revenue!F11 | C23: =Revenue!F13 | D23: =Revenue!J11 | E23: =Revenue!J13 | F23: =C23/B23 | G23: =E23/D23 | H23: =B23/B$25 | I23: =D23/D$25
A24: liquidity | B24: =Revenue!F14 | C24: =Revenue!F16 | D24: =Revenue!J14 | E24: =Revenue!J16 | F24: =C24/B24 | G24: =E24/D24 | H24: =B24/B$25 | I24: =D24/D$25
A25: Total | B25: =SUM(B21:B24) | C25: =SUM(C21:C24) | D25: =SUM(D21:D24) | E25: =SUM(E21:E24)
A27: Volume effect = (A1-A0) x y0 | B27: =(D25-B25)*SUMPRODUCT(H21:H24,F21:F24)
A28: Mix effect = A1 x sum((w1-w0) x y0) | B28: =D25*SUMPRODUCT(I21:I24-H21:H24,F21:F24)
A29: Rate effect = A1 x sum(w1 x (y1-y0)) | B29: =D25*SUMPRODUCT(I21:I24,G21:G24-F21:F24)
A30: Total bridge | B30: =SUM(B27:B29)
A31: Actual change in fees | B31: =E25-C25

Sheet Profitability
A1: Fully allocated profitability by business - trailing four quarters ($m) - SYNTHETIC business split
A2: Allocation method | B2: abc
A4: Business | B4: Revenue T4Q | C4: Contribution T4Q | D4: revenue | E4: headcount | F4: abc | G4: step_down | H4: reciprocal | I4: Selected allocation | J4: Fully allocated pre-tax | K4: Fully allocated margin | L4: Rank | M4: Contribution margin %
A5: PE | B5: 3085.495 | C5: 1438.0977 | D5: 803.3179 | E5: 887.0601 | F5: 810.02901 | G5: 800.84298 | H5: 801.6609 | I5: =INDEX(D5:H5,MATCH($B$2,$D$4:$H$4,0)) | J5: =C5-I5 | K5: =J5/B5 | L5: =RANK(K5,K$5:K$10) | M5: =C5/B5
A6: PWM | B6: 3996.9 | C6: 1664.0875 | D6: 1039.8006 | E6: 1256.1298 | F6: 1197.8312 | G6: 1148.775 | H6: 1162.4186 | I6: =INDEX(D6:H6,MATCH($B$2,$D$4:$H$4,0)) | J6: =C6-I6 | K6: =J6/B6 | L6: =RANK(K6,K$5:K$10) | M6: =C6/B6
A7: PBL | B7: 3160 | C7: 2046.3579 | D7: 822.19587 | E7: 564.65346 | F7: 751.42797 | G7: 803.20181 | H7: 790.58801 | I7: =INDEX(D7:H7,MATCH($B$2,$D$4:$H$4,0)) | J7: =C7-I7 | K7: =J7/B7 | L7: =RANK(K7,K$5:K$10) | M7: =C7/B7
A8: FIMA | B8: 2312.9065 | C8: 1138.7917 | D8: 601.98791 | E8: 632.21562 | F8: 753.64587 | G8: 751.2406 | H8: 751.96677 | I8: =INDEX(D8:H8,MATCH($B$2,$D$4:$H$4,0)) | J8: =C8-I8 | K8: =J8/B8 | L8: =RANK(K8,K$5:K$10) | M8: =C8/B8
A9: LIQ | B9: 343.96172 | C9: 214.7295 | D9: 89.563538 | E9: 69.586581 | F9: 283.97145 | G9: 302.8058 | H9: 299.0827 | I9: =INDEX(D9:H9,MATCH($B$2,$D$4:$H$4,0)) | J9: =C9-I9 | K9: =J9/B9 | L9: =RANK(K9,K$5:K$10) | M9: =C9/B9
A10: ALT | B10: 4997.7368 | C10: 2687.5358 | D10: 1296.7342 | E10: 1243.9544 | F10: 856.69454 | G10: 846.73383 | H10: 847.88298 | I10: =INDEX(D10:H10,MATCH($B$2,$D$4:$H$4,0)) | J10: =C10-I10 | K10: =J10/B10 | L10: =RANK(K10,K$5:K$10) | M10: =C10/B10
A11: Total | B11: =SUM(B5:B10) | C11: =SUM(C5:C10) | D11: =SUM(D5:D10) | E11: =SUM(E5:E10) | F11: =SUM(F5:F10) | G11: =SUM(G5:G10) | H11: =SUM(H5:H10) | I11: =SUM(I5:I10) | J11: =SUM(J5:J10)
A13: Public AWM pre-tax earnings, same four quarters | B13: 4536
A14: Reconciliation difference (must be 0) | B14: =J11-B13
A16: Businesses whose profit sign flips vs revenue-based method are flagged in the Python report (mart_allocation_rank_sensitivity).

Sheet Mandate_Pricing
A1: Mandate pricing - marginal vs fully allocated ($m; fees in bps). Cost inputs are SYNTHETIC (M7/M8).
A4: Initial AUM ($m) | B4: 1000
A5: Net AUM growth p.a. | B5: 0.06
A6: Annual termination hazard | B6: 0.08
A7: Weibull shape (1 = exponential) | B7: 1
A8: Horizon (years, fixed) | B8: 7
A9: PM FTE | B9: 0.6
A10: Client service FTE | B10: 0.3
A11: Loaded cost per FTE ($m) | B11: 1.2017382
A12: Trading / execution (bps) | B12: 1
A13: Custody & admin (bps) | B13: 1.5
A14: Data licences ($m / yr) | B14: 0.05
A15: Onboarding one-off ($m) | B15: 0.25
... A21: Fee schedule scale lambda (Goal Seek this to hit profit = 0) | B21: 1
A22: Weibull scale (from hazard) | B22: =1/(-LN(1-B6))^(1/B7)
A23: Fee tiers: lower bound $m | B23: Upper bound $m | C23: bps
A24: 0 | B24: 250 | C24: 40
A25: 250 | B25: 500 | C25: 32
A26: 500 | B26: 1000000000000 | C26: 24
A28: Year | C28: 1 | D28: 2 | E28: 3 | F28: 4 | G28: 5 | H28: 6 | I28: 7
A29: t | C29: 1 | D29: 2 | E29: 3 | F29: 4 | G29: 5 | H29: 6 | I29: 7
A30: End AUM | C30: =$B$4*(1+$B$5)^C29 | D30: =$B$4*(1+$B$5)^D29 | E30: =$B$4*(1+$B$5)^E29 | F30: =$B$4*(1+$B$5)^F29 | G30: =$B$4*(1+$B$5)^G29 | H30: =$B$4*(1+$B$5)^H29 | I30: =$B$4*(1+$B$5)^I29
A31: Start AUM | C31: =$B$4 | D31: =C30 | E31: =D30 | F31: =E30 | G31: =F30 | H31: =G30 | I31: =H30
A32: Average AUM | C32: =(C30+C31)/2 | D32: =(D30+D31)/2 | E32: =(E30+E31)/2 | F32: =(F30+F31)/2 | G32: =(G30+G31)/2 | H32: =(H30+H31)/2 | I32: =(I30+I31)/2
A33: Revenue at lambda=1 | C33: =SUMPRODUCT((C32>$A$24:$A$26)*((C32<$B$24:$B$26)*C32+(C32>=$B$24:$B$26)*$B$24:$B$26-$A$24:$A$26)*$C$24:$C$26)/10000 | D33: =SUMPRODUCT((D32>$A$24:$A$26)*((D32<$B$24:$B$26)*D32+(D32>=$B$24:$B$26)*$B$24:$B$26-$A$24:$A$26)*$C$24:$C$26)/10000 | E33: =SUMPRODUCT((E32>$A$24:$A$26)*((E32<$B$24:$B$26)*E32+(E32>=$B$24:$B$26)*$B$24:$B$26-$A$24:$A$26)*$C$24:$C$26)/10000 | F33: =SUMPRODUCT((F32>$A$24:$A$26)*((F32<$B$24:$B$26)*F32+(F32>=$B$24:$B$26)*$B$24:$B$26-$A$24:$A$26)*$C$24:$C$26)/10000 | G33: =SUMPRODUCT((G32>$A$24:$A$26)*((G32<$B$24:$B$26)*G32+(G32>=$B$24:$B$26)*$B$24:$B$26-$A$24:$A$26)*$C$24:$C$26)/10000 | H33: =SUMPRODUCT((H32>$A$24:$A$26)*((H32<$B$24:$B$26)*H32+(H32>=$B$24:$B$26)*$B$24:$B$26-$A$24:$A$26)*$C$24:$C$26)/10000 | I33: =SUMPRODUCT((I32>$A$24:$A$26)*((I32<$B$24:$B$26)*I32+(I32>=$B$24:$B$26)*$B$24:$B$26-$A$24:$A$26)*$C$24:$C$26)/10000
A34: Revenue (scaled) | C34: =$B$21*C33 | D34: =$B$21*D33 | E34: =$B$21*E33 | F34: =$B$21*F33 | G34: =$B$21*G33 | H34: =$B$21*H33 | I34: =$B$21*I33
A35: People cost | C35: =($B$9+$B$10)*$B$11*1.03^(C29-1) | D35: =($B$9+$B$10)*$B$11*1.03^(D29-1) | E35: =($B$9+$B$10)*$B$11*1.03^(E29-1) | F35: =($B$9+$B$10)*$B$11*1.03^(F29-1) | G35: =($B$9+$B$10)*$B$11*1.03^(G29-1) | H35: =($B$9+$B$10)*$B$11*1.03^(H29-1) | I35: =($B$9+$B$10)*$B$11*1.03^(I29-1)
A36: Trading + custody | C36: =C32*($B$12+$B$13)/10000 | D36: =D32*($B$12+$B$13)/10000 | E36: =E32*($B$12+$B$13)/10000 | F36: =F32*($B$12+$B$13)/10000 | G36: =G32*($B$12+$B$13)/10000 | H36: =H32*($B$12+$B$13)/10000 | I36: =I32*($B$12+$B$13)/10000
A37: Data licences | C37: =$B$14 | D37: =$B$14 | E37: =$B$14 | F37: =$B$14 | G37: =$B$14 | H37: =$B$14 | I37: =$B$14
A38: Sales commission | C38: =IF(C29=1,$B$16*C34,0) | D38: =IF(D29=1,$B$16*D34,0) | E38: =IF(E29=1,$B$16*E34,0) | F38: =IF(F29=1,$B$16*F34,0) | G38: =IF(G29=1,$B$16*G34,0) | H38: =IF(H29=1,$B$16*H34,0) | I38: =IF(I29=1,$B$16*I34,0)
A39: Capital charge | C39: =$B$17*$B$18 | D39: =$B$17*$B$18 | E39: =$B$17*$B$18 | F39: =$B$17*$B$18 | G39: =$B$17*$B$18 | H39: =$B$17*$B$18 | I39: =$B$17*$B$18
A40: Direct costs | C40: =SUM(C35:C39) | D40: =SUM(D35:D39) | E40: =SUM(E35:E39) | F40: =SUM(F35:F39) | G40: =SUM(G35:G39) | H40: =SUM(H35:H39) | I40: =SUM(I35:I39)
A41: Allocated shared costs | C41: =C32*$B$19/10000 | D41: =D32*$B$19/10000 | E41: =E32*$B$19/10000 | F41: =F32*$B$19/10000 | G41: =G32*$B$19/10000 | H41: =H32*$B$19/10000 | I41: =I32*$B$19/10000
A42: Marginal (contribution) profit | C42: =C34-C40 | D42: =D34-D40 | E42: =E34-E40 | F42: =F34-F40 | G42: =G34-G40 | H42: =H34-H40 | I42: =I34-I40
A43: Fully allocated profit | C43: =C42-C41 | D43: =D42-D41 | E43: =E42-E41 | F43: =F42-F41 | G43: =G42-G41 | H43: =H42-H41 | I43: =I42-I41
A44: Survival S(t-0.5) | C44: =EXP(-((C29-0.5)/$B$22)^$B$7) | D44: =EXP(-((D29-0.5)/$B$22)^$B$7) | E44: =EXP(-((E29-0.5)/$B$22)^$B$7) | F44: =EXP(-((F29-0.5)/$B$22)^$B$7) | G44: =EXP(-((G29-0.5)/$B$22)^$B$7) | H44: =EXP(-((H29-0.5)/$B$22)^$B$7) | I44: =EXP(-((I29-0.5)/$B$22)^$B$7)
A45: Discount factor | C45: =(1+$B$20)^-(C29-0.5) | D45: =(1+$B$20)^-(D29-0.5) | E45: =(1+$B$20)^-(E29-0.5) | F45: =(1+$B$20)^-(F29-0.5) | G45: =(1+$B$20)^-(G29-0.5) | H45: =(1+$B$20)^-(H29-0.5) | I45: =(1+$B$20)^-(I29-0.5)
A46: PV marginal | C46: =C44*C45*C42 | D46: =D44*D45*D42 | E46: =E44*E45*E42 | F46: =F44*F45*F42 | G46: =G44*G45*G42 | H46: =H44*H45*H42 | I46: =I44*I45*I42
A47: PV fully allocated | C47: =C44*C45*C43 | D47: =D44*D45*D43 | E47: =E44*E45*E43 | F47: =F44*F45*F43 | G47: =G44*G45*G43 | H47: =H44*H45*H43 | I47: =I44*I45*I43
A48: Direct costs excl. commission | C48: =C35+C36+C37+C39 | D48: =D35+D36+D37+D39 | E48: =E35+E36+E37+E39 | F48: =F35+F36+F37+F39 | G48: =G35+G36+G37+G39 | H48: =H35+H36+H37+H39 | I48: =I35+I36+I37+I39
...

Sheet Growth_Case
A1: Growth Markets: GCC private wealth office - 7-year business case ($m). ILLUSTRATIVE assumptions.
A2: Location | B2: DIFC
A4: Location | B4: Cost index | C4: Set-up capex | D4: Licence $m/yr | E4: Tax rate | F4: Note (VERIFY tax)
A5: DIFC | B5: 1 | C5: 4 | D5: 0.6 | E5: 0.09 | F5: Dubai; UAE CT 9%, qualifying free-zone income may be 0% - VERIFY
A6: KAFD | B6: 0.92 | C6: 4.5 | D6: 0.5 | E6: 0.2 | F6: Riyadh; KSA CIT 20% on foreign share - VERIFY
A7: ADGM | B7: 0.98 | C7: 3.8 | D7: 0.5 | E7: 0.09 | F7: Abu Dhabi; UAE CT 9% - VERIFY
A9: Selected cost index | B9: =INDEX(B5:B7,MATCH(B2,A5:A7,0))
A10: Selected set-up capex | B10: =INDEX(C5:C7,MATCH(B2,A5:A7,0))
A11: Selected licence $m/yr | B11: =INDEX(D5:D7,MATCH(B2,A5:A7,0))
A12: Selected tax rate | B12: =INDEX(E5:E7,MATCH(B2,A5:A7,0))
A14: Advisor attrition p.a. | B14: 0.08
A15: Support staff per advisor | B15: 0.4
A16: Core staff (fixed) | B16: 8
A17: Mature AUM per advisor ($m) | B17: 400
A18: Ramp midpoint (years) | B18: 1.5
A19: Ramp steepness | B19: 1.6
A20: Client attrition p.a. | B20: 0.05
A21: Net revenue (bps of AUM) | B21: 85
A22: Advisor cost ($m) | B22: 0.65
A23: Support cost ($m) | B23: 0.25
A24: Premises & tech per head ($m) | B24: 0.06
A25: Cost inflation | B25: 0.03
... A29: Variable comp (% of revenue) | B29: 0.1
A31: Year | B31: 0 | C31: 1 | D31: 2 | E31: 3 | F31: 4 | G31: 5 | H31: 6 | I31: 7
A32: Gross advisor hires | C32: 6 | D32: 8 | E32: 8 | F32: 8 | G32: 6 | H32: 4 | I32: 4
A33: Year index | C33: 1 | D33: 2 | E33: 3 | F33: 4 | G33: 5 | H33: 6 | I33: 7
A35: Advisors alive by hire cohort (rows) and year (columns)
A36: Cohort hired Y1 | C36: =C$32*(1-$B$14)^(C$33-C$33) | D36: =C$32*(1-$B$14)^(D$33-C$33) | E36: =C$32*(1-$B$14)^(E$33-C$33) | F36: =C$32*(1-$B$14)^(F$33-C$33) | G36: =C$32*(1-$B$14)^(G$33-C$33) | H36: =C$32*(1-$B$14)^(H$33-C$33) | I36: =C$32*(1-$B$14)^(I$33-C$33)
A37: Cohort hired Y2 | C37: 0 | D37: =D$32*(1-$B$14)^(D$33-D$33) | E37: =D$32*(1-$B$14)^(E$33-D$33) | F37: =D$32*(1-$B$14)^(F$33-D$33) | G37: =D$32*(1-$B$14)^(G$33-D$33) | H37: =D$32*(1-$B$14)^(H$33-D$33) | I37: =D$32*(1-$B$14)^(I$33-D$33)
A38: Cohort hired Y3 | C38: 0 | D38: 0 | E38: =E$32*(1-$B$14)^(E$33-E$33) | F38: =E$32*(1-$B$14)^(F$33-E$33) | G38: =E$32*(1-$B$14)^(G$33-E$33) | H38: =E$32*(1-$B$14)^(H$33-E$33) | I38: =E$32*(1-$B$14)^(I$33-E$33)
A39: Cohort hired Y4 | C39: 0 | D39: 0 | E39: 0 | F39: =F$32*(1-$B$14)^(F$33-F$33) | G39: =F$32*(1-$B$14)^(G$33-F$33) | H39: =F$32*(1-$B$14)^(H$33-F$33) | I39: =F$32*(1-$B$14)^(I$33-F$33)
A40: Cohort hired Y5 | C40: 0 | D40: 0 | E40: 0 | F40: 0 | G40: =G$32*(1-$B$14)^(G$33-G$33) | H40: =G$32*(1-$B$14)^(H$33-G$33) | I40: =G$32*(1-$B$14)^(I$33-G$33)
A41: Cohort hired Y6 | C41: 0 | D41: 0 | E41: 0 | F41: 0 | G41: 0 | H41: =H$32*(1-$B$14)^(H$33-H$33) | I41: =H$32*(1-$B$14)^(I$33-H$33)
A42: Cohort hired Y7 | C42: 0 | D42: 0 | E42: 0 | F42: 0 | G42: 0 | H42: 0 | I42: =I$32*(1-$B$14)^(I$33-I$33)
A44: Client AUM at year end by cohort ($m)
A45: Cohort hired Y1 | C45: =C36*$B$17/(1+EXP(-$B$19*((C$33-C$33+0.5)-$B$18)))*(1-$B$20)^(C$33-C$33) | D45: =D36*$B$17/(1+EXP(-$B$19*((D$33-C$33+0.5)-$B$18)))*(1-$B$20)^(D$33-C$33) | E45: =E36*$B$17/(1+EXP(-$B$19*((E$33-C$33+0.5)-$B$18)))*(1-$B$20)^(E$33-C$33) | F45: =F36*$B$17/(1+EXP(-$B$19*((F$33-C$33+0.5)-$B$18)))*(1-$B$20)^(F$33-C$33) | G45: =G36*$B$17/(1+EXP(-$B$19*((G$33-C$33+0.5)-$B$18)))*(1-$B$20)^(G$33-C$33) | H45: =H36*$B$17/(1+EXP(-$B$19*((H$33-C$33+0.5)-$B$18)))*(1-$B$20)^(H$33-C$33) | I45: =I36*$B$17/(1+EXP(-$B$19*((I$33-C$33+0.5)-$B$18)))*(1-$B$20)^(I$33-C$33)
A46: Cohort hired Y2 | C46: 0 | D46: =D37*$B$17/(1+EXP(-$B$19*((D$33-D$33+0.5)-$B$18)))*(1-$B$20)^(D$33-D$33) | E46: =E37*$B$17/(1+EXP(-$B$19*((E$33-D$33+0.5)-$B$18)))*(1-$B$20)^(E$33-D$33) | F46: =F37*$B$17/(1+EXP(-$B$19*((F$33-D$33+0.5)-$B$18)))*(1-$B$20)^(F$33-D$33) | G46: =G37*$B$17/(1+EXP(-$B$19*((G$33-D$33+0.5)-$B$18)))*(1-$B$20)^(G$33-D$33) | H46: =H37*$B$17/(1+EXP(-$B$19*((H$33-D$33+0.5)-$B$18)))*(1-$B$20)^(H$33-D$33) | I46: =I37*$B$17/(1+EXP(-$B$19*((I$33-D$33+0.5)-$B$18)))*(1-$B$20)^(I$33-D$33)
A47: Cohort hired Y3 | C47: 0 | D47: 0 | E47: =E38*$B$17/(1+EXP(-$B$19*((E$33-E$33+0.5)-$B$18)))*(1-$B$20)^(E$33-E$33) | F47: =F38*$B$17/(1+EXP(-$B$19*((F$33-E$33+0.5)-$B$18)))*(1-$B$20)^(F$33-E$33) | G47: =G38*$B$17/(1+EXP(-$B$19*((G$33-E$33+0.5)-$B$18)))*(1-$B$20)^(G$33-E$33) | H47: =H38*$B$17/(1+EXP(-$B$19*((H$33-E$33+0.5)-$B$18)))*(1-$B$20)^(H$33-E$33) | I47: =I38*$B$17/(1+EXP(-$B$19*((I$33-E$33+0.5)-$B$18)))*(1-$B$20)^(I$33-E$33)
A48: Cohort hired Y4 | C48: 0 | D48: 0 | E48: 0 | F48: =F39*$B$17/(1+EXP(-$B$19*((F$33-F$33+0.5)-$B$18)))*(1-$B$20)^(F$33-F$33) | G48: =G39*$B$17/(1+EXP(-$B$19*((G$33-F$33+0.5)-$B$18)))*(1-$B$20)^(G$33-F$33) | H48: =H39*$B$17/(1+EXP(-$B$19*((H$33-F$33+0.5)-$B$18)))*(1-$B$20)^(H$33-F$33) | I48: =I39*$B$17/(1+EXP(-$B$19*((I$33-F$33+0.5)-$B$18)))*(1-$B$20)^(I$33-F$33)
A49: Cohort hired Y5 | C49: 0 | D49: 0 | E49: 0 | F49: 0 | G49: =G40*$B$17/(1+EXP(-$B$19*((G$33-G$33+0.5)-$B$18)))*(1-$B$20)^(G$33-G$33) | H49: =H40*$B$17/(1+EXP(-$B$19*((H$33-G$33+0.5)-$B$18)))*(1-$B$20)^(H$33-G$33) | I49: =I40*$B$17/(1+EXP(-$B$19*((I$33-G$33+0.5)-$B$18)))*(1-$B$20)^(I$33-G$33)
...

Sheet Sensitivity
A1: First-order sensitivity of Year-2 Q4 (t8) pre-tax earnings to fee yield and equity-market shock ($m)
A2: Approximation: dRev = fees x dYield + shock x sum(fees_k x beta_k); dPreTax = dRev x (1 - comp ratio - variable non-comp). Valid while the comp floor is not binding.
A4: Pre-tax t8 (model) | B4: =PnL!J10
A5: Management fees t8 | B5: =Revenue!J17
A6: Equity-beta-weighted fees t8 | B6: =Revenue!J7*Inputs!F13+Revenue!J10*Inputs!F14+Revenue!J13*Inputs!F15+Revenue!J16*Inputs!F16
A7: Pre-tax flow-through (1 - comp ratio - variable non-comp) | B7: =1-Inputs!B19-Inputs!B21
A9: Fee-yield change \ equity shock | B9: -0.2 | C9: -0.1 | D9: 0 | E9: 0.1 | F9: 0.2
A10: -0.1 | B10: =$B$4+($B$5*$A10+B$9*$B$6)*$B$7 | C10: =$B$4+($B$5*$A10+C$9*$B$6)*$B$7 | D10: =$B$4+($B$5*$A10+D$9*$B$6)*$B$7 | E10: =$B$4+($B$5*$A10+E$9*$B$6)*$B$7 | F10: =$B$4+($B$5*$A10+F$9*$B$6)*$B$7
A11: -0.05 | B11: =$B$4+($B$5*$A11+B$9*$B$6)*$B$7 | C11: =$B$4+($B$5*$A11+C$9*$B$6)*$B$7 | D11: =$B$4+($B$5*$A11+D$9*$B$6)*$B$7 | E11: =$B$4+($B$5*$A11+E$9*$B$6)*$B$7 | F11: =$B$4+($B$5*$A11+F$9*$B$6)*$B$7
A12: 0 | B12: =$B$4+($B$5*$A12+B$9*$B$6)*$B$7 | C12: =$B$4+($B$5*$A12+C$9*$B$6)*$B$7 | D12: =$B$4+($B$5*$A12+D$9*$B$6)*$B$7 | E12: =$B$4+($B$5*$A12+E$9*$B$6)*$B$7 | F12: =$B$4+($B$5*$A12+F$9*$B$6)*$B$7
A13: 0.05 | B13: =$B$4+($B$5*$A13+B$9*$B$6)*$B$7 | C13: =$B$4+($B$5*$A13+C$9*$B$6)*$B$7 | D13: =$B$4+($B$5*$A13+D$9*$B$6)*$B$7 | E13: =$B$4+($B$5*$A13+E$9*$B$6)*$B$7 | F13: =$B$4+($B$5*$A13+F$9*$B$6)*$B$7
A14: 0.1 | B14: =$B$4+($B$5*$A14+B$9*$B$6)*$B$7 | C14: =$B$4+($B$5*$A14+C$9*$B$6)*$B$7 | D14: =$B$4+($B$5*$A14+D$9*$B$6)*$B$7 | E14: =$B$4+($B$5*$A14+E$9*$B$6)*$B$7 | F14: =$B$4+($B$5*$A14+F$9*$B$6)*$B$7

Sheet Benchmarks
A1: Peer benchmarks - latest quarter with data, trailing-four-quarter basis. Pasted from the warehouse (mart_peer_benchmark).
A3: Ticker | B3: Period | C3: AUM/AUS $m | D3: Fee yield T4Q (bps) | E3: Organic growth T4Q | F3: Op margin T4Q | G3: Comp ratio T4Q | H3: z fee yield | I3: z organic | J3: z margin
A4: BEN | B4: 2026-06-30 | C4: 1791600 | D4: 43.78679 | E4: 0.038342226 | G4: 0.42466297 | H4: =IF(ISNUMBER(D4),(D4-AVERAGE(D$4:D$10))/STDEV(D$4:D$10),"") | I4: =IF(ISNUMBER(E4),(E4-AVERAGE(E$4:E$10))/STDEV(E$4:E$10),"") | J4: =IF(ISNUMBER(F4),(F4-AVERAGE(F$4:F$10))/STDEV(F$4:F$10),"")
A5: BLK | B5: 2026-09-30 | C5: 15488263 | D5: 15.567375 | E5: 0.064514646 | F5: 0.32457431 | G5: 0.33364866 | H5: =IF(ISNUMBER(D5),(D5-AVERAGE(D$4:D$10))/STDEV(D$4:D$10),"") | I5: =IF(ISNUMBER(E5),(E5-AVERAGE(E$4:E$10))/STDEV(E$4:E$10),"") | J5: =IF(ISNUMBER(F5),(F5-AVERAGE(F$4:F$10))/STDEV(F$4:F$10),"")
A6: GS | B6: 2026-09-30 | C6: 4097000 | D6: 34.778224 | E6: 0.14947856 | H6: =IF(ISNUMBER(D6),(D6-AVERAGE(D$4:D$10))/STDEV(D$4:D$10),"") | I6: =IF(ISNUMBER(E6),(E6-AVERAGE(E$4:E$10))/STDEV(E$4:E$10),"") | J6: =IF(ISNUMBER(F6),(F6-AVERAGE(F$4:F$10))/STDEV(F$4:F$10),"")
A7: IVZ | B7: 2026-06-30 | C7: 2470300 | D7: 23.873597 | E7: 0.076246627 | G7: 0.30238319 | H7: =IF(ISNUMBER(D7),(D7-AVERAGE(D$4:D$10))/STDEV(D$4:D$10),"") | I7: =IF(ISNUMBER(E7),(E7-AVERAGE(E$4:E$10))/STDEV(E$4:E$10),"") | J7: =IF(ISNUMBER(F7),(F7-AVERAGE(F$4:F$10))/STDEV(F$4:F$10),"")
A8: JPM | B8: 2026-06-30 | C8: 5140000 | D8: 35.113237 | E8: 0.093253511 | F8: 0.36800093 | G8: 0.35254001 | H8: =IF(ISNUMBER(D8),(D8-AVERAGE(D$4:D$10))/STDEV(D$4:D$10),"") | I8: =IF(ISNUMBER(E8),(E8-AVERAGE(E$4:E$10))/STDEV(E$4:E$10),"") | J8: =IF(ISNUMBER(F8),(F8-AVERAGE(F$4:F$10))/STDEV(F$4:F$10),"")
A9: MS | B9: 2026-06-30 | C9: 2004000 | D9: 33.358013 | E9: 0.10099241 | F9: 0.23137973 | G9: 0.36462149 | H9: =IF(ISNUMBER(D9),(D9-AVERAGE(D$4:D$10))/STDEV(D$4:D$10),"") | I9: =IF(ISNUMBER(E9),(E9-AVERAGE(E$4:E$10))/STDEV(E$4:E$10),"") | J9: =IF(ISNUMBER(F9),(F9-AVERAGE(F$4:F$10))/STDEV(F$4:F$10),"")
A10: TROW | B10: 2026-06-30 | C10: 1893400 | D10: 38.609537 | E10: -0.031965649 | F10: 0.30758693 | G10: 0.38975237 | H10: =IF(ISNUMBER(D10),(D10-AVERAGE(D$4:D$10))/STDEV(D$4:D$10),"") | I10: =IF(ISNUMBER(E10),(E10-AVERAGE(E$4:E$10))/STDEV(E$4:E$10),"") | J10: =IF(ISNUMBER(F10),(F10-AVERAGE(F$4:F$10))/STDEV(F$4:F$10),"")
A13: Comparability: see warehouse table comparability_flags. GS = AWM segment/AUS; BLK = whole firm, residual market; IVZ gross fees; margins are GAAP-operating.

Sheet Checks
A1: Model integrity checks - every value must be 0
A3: Check | B3: Value (0 = pass)
A4: AUS roll-forward closes in every quarter | B4: =SUMPRODUCT(ABS(AUM_Rollforward!C35:J35-AUM_Rollforward!C32:J32-AUM_Rollforward!C33:J33-AUM_Rollforward!C34:J34))
A5: Fee-yield calibration reproduces base-quarter fees | B5: =ABS(Inputs!B4-SUMPRODUCT(Inputs!I13:I16,Inputs!J13:J16)/4)
A6: Net revenue = fees + incentive + PBL + investments | B6: =SUMPRODUCT(ABS(Revenue!C22:J22-Revenue!C17:J17-Revenue!C19:J19-Revenue!C20:J20-Revenue!C21:J21))
A7: Pre-tax = revenue - comp - non-comp - provision | B7: =SUMPRODUCT(ABS(PnL!C10:J10-PnL!C5:J5+Expenses!C8:J8))
A8: Costs are non-negative (sign convention) | B8: =SUMPRODUCT(--(Expenses!C5:J8<0))
A9: Compensation never below the fixed floor | B9: =SUMPRODUCT(--(Expenses!C5:J5<Inputs!B28-0.000001))
A10: Price-volume-mix effects sum to the fee change | B10: =ABS(Budget_Variance!B30-Budget_Variance!B31)
A11: Fully allocated pre-tax reconciles to the public segment | B11: =ABS(Profitability!B14)
A12: Mandate: profit is zero at the year-1 marginal break-even fee | B12: =ABS(Mandate_Pricing!B54*Mandate_Pricing!C33*(1-Mandate_Pricing!B16)-Mandate_Pricing!C48)
A13: Mandate: profit is zero at the year-1 fully allocated break-even fee | B13: =ABS(Mandate_Pricing!B55*Mandate_Pricing!C33*(1-Mandate_Pricing!B16)-Mandate_Pricing!C48-Mandate_Pricing!C41)
A14: Growth case: NPV at the IRR is zero | B14: =ABS(Growth_Case!B66+NPV(Growth_Case!B78,Growth_Case!C79:I79))
A15: Scenario selector is a valid scenario name | B15: =IF(COUNTIF(Scenarios!A20:A59,Scenarios!B2)>0,0,1)
A16: Growth-case location is valid | B16: =IF(COUNTIF(Growth_Case!A5:A7,Growth_Case!B2)>0,0,1)
A18: Number of checks | B18: 13
A19: Sum of absolute check values | B19: =SUMPRODUCT(ABS(B4:B16))
